2019-01-02 13:38:13,952 - root - INFO - Database initialized.
2019-01-02 13:38:14,007 - root - INFO - "users" table initialized.
2019-01-02 13:38:14,016 - root - INFO - "skill_categories" table initialized.
2019-01-02 13:38:14,029 - root - INFO - "skills" table initialized.
2019-01-02 13:38:14,041 - root - INFO - "person_skills" table initialized.
2019-01-02 13:38:14,049 - root - INFO - "job_status" table initialized.
2019-01-02 13:38:14,066 - root - INFO - "available_jobs" table initialized.
2019-01-02 13:38:14,081 - root - INFO - "pending_jobs" table initialized.
2019-01-02 14:58:10,106 - root - INFO - Database initialized.
2019-01-02 14:58:10,730 - root - INFO - "users" table initialized.
2019-01-02 14:58:11,220 - root - INFO - "skill_categories" table initialized.
2019-01-02 14:58:11,721 - root - INFO - "skills" table initialized.
2019-01-02 14:58:12,443 - root - INFO - "person_skills" table initialized.
2019-01-02 14:58:12,882 - root - INFO - "statuses" table initialized.
2019-01-02 14:58:13,634 - root - INFO - "jobs" table initialized.
2019-01-02 14:58:13,634 - root - INFO - Complete database initialized.
2019-01-02 14:58:14,406 - root - ERROR - Not enough parameters for the SQL statement
Traceback (most recent call last):
  File "C:\Users\Ari\PycharmProjects\ITC_hackathon\venv\lib\site-packages\mysql\connector\cursor_cext.py", line 65, in __call__
    return self.params[index]
IndexError: tuple index out of range

During handling of the above exception, another exception occurred:

Traceback (most recent call last):
  File "C:\Users\Ari\PycharmProjects\ITC_hackathon\database_queries.py", line 133, in populate_skill_categories
    cur.execute(the_query, insert_string)
  File "C:\Users\Ari\PycharmProjects\ITC_hackathon\venv\lib\site-packages\mysql\connector\cursor_cext.py", line 258, in execute
    stmt = RE_PY_PARAM.sub(psub, stmt)
  File "C:\Users\Ari\PycharmProjects\ITC_hackathon\venv\lib\site-packages\mysql\connector\cursor_cext.py", line 68, in __call__
    "Not enough parameters for the SQL statement")
mysql.connector.errors.ProgrammingError: Not enough parameters for the SQL statement
2019-01-02 14:58:14,422 - root - ERROR - Not enough parameters for the SQL statement
Traceback (most recent call last):
  File "C:\Users\Ari\PycharmProjects\ITC_hackathon\venv\lib\site-packages\mysql\connector\cursor_cext.py", line 65, in __call__
    return self.params[index]
IndexError: tuple index out of range

During handling of the above exception, another exception occurred:

Traceback (most recent call last):
  File "C:\Users\Ari\PycharmProjects\ITC_hackathon\database_queries.py", line 133, in populate_skill_categories
    cur.execute(the_query, insert_string)
  File "C:\Users\Ari\PycharmProjects\ITC_hackathon\venv\lib\site-packages\mysql\connector\cursor_cext.py", line 258, in execute
    stmt = RE_PY_PARAM.sub(psub, stmt)
  File "C:\Users\Ari\PycharmProjects\ITC_hackathon\venv\lib\site-packages\mysql\connector\cursor_cext.py", line 68, in __call__
    "Not enough parameters for the SQL statement")
mysql.connector.errors.ProgrammingError: Not enough parameters for the SQL statement
2019-01-02 14:58:14,437 - root - ERROR - Not enough parameters for the SQL statement
Traceback (most recent call last):
  File "C:\Users\Ari\PycharmProjects\ITC_hackathon\venv\lib\site-packages\mysql\connector\cursor_cext.py", line 65, in __call__
    return self.params[index]
IndexError: tuple index out of range

During handling of the above exception, another exception occurred:

Traceback (most recent call last):
  File "C:\Users\Ari\PycharmProjects\ITC_hackathon\database_queries.py", line 133, in populate_skill_categories
    cur.execute(the_query, insert_string)
  File "C:\Users\Ari\PycharmProjects\ITC_hackathon\venv\lib\site-packages\mysql\connector\cursor_cext.py", line 258, in execute
    stmt = RE_PY_PARAM.sub(psub, stmt)
  File "C:\Users\Ari\PycharmProjects\ITC_hackathon\venv\lib\site-packages\mysql\connector\cursor_cext.py", line 68, in __call__
    "Not enough parameters for the SQL statement")
mysql.connector.errors.ProgrammingError: Not enough parameters for the SQL statement
2019-01-02 14:58:14,453 - root - ERROR - Not enough parameters for the SQL statement
Traceback (most recent call last):
  File "C:\Users\Ari\PycharmProjects\ITC_hackathon\venv\lib\site-packages\mysql\connector\cursor_cext.py", line 65, in __call__
    return self.params[index]
IndexError: tuple index out of range

During handling of the above exception, another exception occurred:

Traceback (most recent call last):
  File "C:\Users\Ari\PycharmProjects\ITC_hackathon\database_queries.py", line 133, in populate_skill_categories
    cur.execute(the_query, insert_string)
  File "C:\Users\Ari\PycharmProjects\ITC_hackathon\venv\lib\site-packages\mysql\connector\cursor_cext.py", line 258, in execute
    stmt = RE_PY_PARAM.sub(psub, stmt)
  File "C:\Users\Ari\PycharmProjects\ITC_hackathon\venv\lib\site-packages\mysql\connector\cursor_cext.py", line 68, in __call__
    "Not enough parameters for the SQL statement")
mysql.connector.errors.ProgrammingError: Not enough parameters for the SQL statement
2019-01-02 14:58:14,484 - root - ERROR - list index out of range
Traceback (most recent call last):
  File "C:\Users\Ari\PycharmProjects\ITC_hackathon\database_queries.py", line 153, in populate_skills
    insert_string = [result[0][0], details['skill']]
IndexError: list index out of range
2019-01-02 14:58:14,500 - root - ERROR - list index out of range
Traceback (most recent call last):
  File "C:\Users\Ari\PycharmProjects\ITC_hackathon\database_queries.py", line 153, in populate_skills
    insert_string = [result[0][0], details['skill']]
IndexError: list index out of range
2019-01-02 14:58:14,516 - root - ERROR - list index out of range
Traceback (most recent call last):
  File "C:\Users\Ari\PycharmProjects\ITC_hackathon\database_queries.py", line 153, in populate_skills
    insert_string = [result[0][0], details['skill']]
IndexError: list index out of range
2019-01-02 14:58:14,531 - root - ERROR - list index out of range
Traceback (most recent call last):
  File "C:\Users\Ari\PycharmProjects\ITC_hackathon\database_queries.py", line 153, in populate_skills
    insert_string = [result[0][0], details['skill']]
IndexError: list index out of range
2019-01-02 14:58:14,547 - root - ERROR - list index out of range
Traceback (most recent call last):
  File "C:\Users\Ari\PycharmProjects\ITC_hackathon\database_queries.py", line 153, in populate_skills
    insert_string = [result[0][0], details['skill']]
IndexError: list index out of range
2019-01-02 14:58:14,577 - root - ERROR - list index out of range
Traceback (most recent call last):
  File "C:\Users\Ari\PycharmProjects\ITC_hackathon\database_queries.py", line 153, in populate_skills
    insert_string = [result[0][0], details['skill']]
IndexError: list index out of range
2019-01-02 14:58:14,596 - root - ERROR - list index out of range
Traceback (most recent call last):
  File "C:\Users\Ari\PycharmProjects\ITC_hackathon\database_queries.py", line 153, in populate_skills
    insert_string = [result[0][0], details['skill']]
IndexError: list index out of range
2019-01-02 14:58:15,061 - root - ERROR - list index out of range
Traceback (most recent call last):
  File "C:\Users\Ari\PycharmProjects\ITC_hackathon\database_queries.py", line 229, in insert_person_skills
    insert_string = [the_username[0][0], the_skill[0][0]]
IndexError: list index out of range
2019-01-02 14:58:15,077 - root - ERROR - list index out of range
Traceback (most recent call last):
  File "C:\Users\Ari\PycharmProjects\ITC_hackathon\database_queries.py", line 229, in insert_person_skills
    insert_string = [the_username[0][0], the_skill[0][0]]
IndexError: list index out of range
2019-01-02 14:58:15,093 - root - ERROR - list index out of range
Traceback (most recent call last):
  File "C:\Users\Ari\PycharmProjects\ITC_hackathon\database_queries.py", line 229, in insert_person_skills
    insert_string = [the_username[0][0], the_skill[0][0]]
IndexError: list index out of range
2019-01-02 14:58:15,108 - root - ERROR - list index out of range
Traceback (most recent call last):
  File "C:\Users\Ari\PycharmProjects\ITC_hackathon\database_queries.py", line 229, in insert_person_skills
    insert_string = [the_username[0][0], the_skill[0][0]]
IndexError: list index out of range
2019-01-02 14:58:15,140 - root - ERROR - list index out of range
Traceback (most recent call last):
  File "C:\Users\Ari\PycharmProjects\ITC_hackathon\database_queries.py", line 229, in insert_person_skills
    insert_string = [the_username[0][0], the_skill[0][0]]
IndexError: list index out of range
2019-01-02 14:58:15,155 - root - ERROR - list index out of range
Traceback (most recent call last):
  File "C:\Users\Ari\PycharmProjects\ITC_hackathon\database_queries.py", line 229, in insert_person_skills
    insert_string = [the_username[0][0], the_skill[0][0]]
IndexError: list index out of range
2019-01-02 14:58:15,171 - root - ERROR - list index out of range
Traceback (most recent call last):
  File "C:\Users\Ari\PycharmProjects\ITC_hackathon\database_queries.py", line 229, in insert_person_skills
    insert_string = [the_username[0][0], the_skill[0][0]]
IndexError: list index out of range
2019-01-02 14:58:15,186 - root - ERROR - list index out of range
Traceback (most recent call last):
  File "C:\Users\Ari\PycharmProjects\ITC_hackathon\database_queries.py", line 229, in insert_person_skills
    insert_string = [the_username[0][0], the_skill[0][0]]
IndexError: list index out of range
2019-01-02 14:58:15,202 - root - ERROR - list index out of range
Traceback (most recent call last):
  File "C:\Users\Ari\PycharmProjects\ITC_hackathon\database_queries.py", line 229, in insert_person_skills
    insert_string = [the_username[0][0], the_skill[0][0]]
IndexError: list index out of range
2019-01-02 14:58:15,218 - root - ERROR - list index out of range
Traceback (most recent call last):
  File "C:\Users\Ari\PycharmProjects\ITC_hackathon\database_queries.py", line 229, in insert_person_skills
    insert_string = [the_username[0][0], the_skill[0][0]]
IndexError: list index out of range
2019-01-02 14:58:15,233 - root - ERROR - list index out of range
Traceback (most recent call last):
  File "C:\Users\Ari\PycharmProjects\ITC_hackathon\database_queries.py", line 229, in insert_person_skills
    insert_string = [the_username[0][0], the_skill[0][0]]
IndexError: list index out of range
2019-01-02 14:58:15,265 - root - ERROR - list index out of range
Traceback (most recent call last):
  File "C:\Users\Ari\PycharmProjects\ITC_hackathon\database_queries.py", line 277, in create_job
    insert_string = [the_username[0][0], the_skill[0][0], the_status[0][0]]
IndexError: list index out of range
2019-01-02 14:58:15,280 - root - ERROR - list index out of range
Traceback (most recent call last):
  File "C:\Users\Ari\PycharmProjects\ITC_hackathon\database_queries.py", line 277, in create_job
    insert_string = [the_username[0][0], the_skill[0][0], the_status[0][0]]
IndexError: list index out of range
2019-01-02 14:58:15,296 - root - ERROR - list index out of range
Traceback (most recent call last):
  File "C:\Users\Ari\PycharmProjects\ITC_hackathon\database_queries.py", line 277, in create_job
    insert_string = [the_username[0][0], the_skill[0][0], the_status[0][0]]
IndexError: list index out of range
2019-01-02 14:58:15,330 - root - ERROR - list index out of range
Traceback (most recent call last):
  File "C:\Users\Ari\PycharmProjects\ITC_hackathon\database_queries.py", line 277, in create_job
    insert_string = [the_username[0][0], the_skill[0][0], the_status[0][0]]
IndexError: list index out of range
2019-01-02 14:58:15,344 - root - ERROR - list index out of range
Traceback (most recent call last):
  File "C:\Users\Ari\PycharmProjects\ITC_hackathon\database_queries.py", line 277, in create_job
    insert_string = [the_username[0][0], the_skill[0][0], the_status[0][0]]
IndexError: list index out of range
2019-01-02 14:58:15,360 - root - ERROR - list index out of range
Traceback (most recent call last):
  File "C:\Users\Ari\PycharmProjects\ITC_hackathon\database_queries.py", line 277, in create_job
    insert_string = [the_username[0][0], the_skill[0][0], the_status[0][0]]
IndexError: list index out of range
2019-01-02 14:58:15,375 - root - ERROR - list index out of range
Traceback (most recent call last):
  File "C:\Users\Ari\PycharmProjects\ITC_hackathon\database_queries.py", line 277, in create_job
    insert_string = [the_username[0][0], the_skill[0][0], the_status[0][0]]
IndexError: list index out of range
2019-01-02 14:58:15,407 - root - ERROR - list index out of range
Traceback (most recent call last):
  File "C:\Users\Ari\PycharmProjects\ITC_hackathon\database_queries.py", line 277, in create_job
    insert_string = [the_username[0][0], the_skill[0][0], the_status[0][0]]
IndexError: list index out of range
2019-01-02 14:58:15,422 - root - ERROR - list index out of range
Traceback (most recent call last):
  File "C:\Users\Ari\PycharmProjects\ITC_hackathon\database_queries.py", line 277, in create_job
    insert_string = [the_username[0][0], the_skill[0][0], the_status[0][0]]
IndexError: list index out of range
2019-01-02 14:58:15,438 - root - ERROR - list index out of range
Traceback (most recent call last):
  File "C:\Users\Ari\PycharmProjects\ITC_hackathon\database_queries.py", line 277, in create_job
    insert_string = [the_username[0][0], the_skill[0][0], the_status[0][0]]
IndexError: list index out of range
2019-01-02 14:58:15,453 - root - ERROR - list index out of range
Traceback (most recent call last):
  File "C:\Users\Ari\PycharmProjects\ITC_hackathon\database_queries.py", line 277, in create_job
    insert_string = [the_username[0][0], the_skill[0][0], the_status[0][0]]
IndexError: list index out of range
2019-01-02 14:58:15,485 - root - ERROR - list index out of range
Traceback (most recent call last):
  File "C:\Users\Ari\PycharmProjects\ITC_hackathon\database_queries.py", line 277, in create_job
    insert_string = [the_username[0][0], the_skill[0][0], the_status[0][0]]
IndexError: list index out of range
2019-01-02 14:59:26,544 - root - INFO - Database initialized.
2019-01-02 14:59:27,213 - root - INFO - "users" table initialized.
2019-01-02 14:59:27,728 - root - INFO - "skill_categories" table initialized.
2019-01-02 14:59:28,901 - root - INFO - "skills" table initialized.
2019-01-02 14:59:31,033 - root - INFO - "person_skills" table initialized.
2019-01-02 14:59:31,884 - root - INFO - "statuses" table initialized.
2019-01-02 14:59:32,665 - root - INFO - "jobs" table initialized.
2019-01-02 14:59:32,665 - root - INFO - Complete database initialized.
2019-01-02 14:59:33,506 - root - ERROR - Not enough parameters for the SQL statement
Traceback (most recent call last):
  File "C:\Users\Ari\PycharmProjects\ITC_hackathon\venv\lib\site-packages\mysql\connector\cursor_cext.py", line 65, in __call__
    return self.params[index]
IndexError: tuple index out of range

During handling of the above exception, another exception occurred:

Traceback (most recent call last):
  File "C:\Users\Ari\PycharmProjects\ITC_hackathon\database_queries.py", line 132, in populate_skill_categories
    cur.execute(the_query, insert_string)
  File "C:\Users\Ari\PycharmProjects\ITC_hackathon\venv\lib\site-packages\mysql\connector\cursor_cext.py", line 258, in execute
    stmt = RE_PY_PARAM.sub(psub, stmt)
  File "C:\Users\Ari\PycharmProjects\ITC_hackathon\venv\lib\site-packages\mysql\connector\cursor_cext.py", line 68, in __call__
    "Not enough parameters for the SQL statement")
mysql.connector.errors.ProgrammingError: Not enough parameters for the SQL statement
2019-01-02 14:59:33,537 - root - ERROR - Not enough parameters for the SQL statement
Traceback (most recent call last):
  File "C:\Users\Ari\PycharmProjects\ITC_hackathon\venv\lib\site-packages\mysql\connector\cursor_cext.py", line 65, in __call__
    return self.params[index]
IndexError: tuple index out of range

During handling of the above exception, another exception occurred:

Traceback (most recent call last):
  File "C:\Users\Ari\PycharmProjects\ITC_hackathon\database_queries.py", line 132, in populate_skill_categories
    cur.execute(the_query, insert_string)
  File "C:\Users\Ari\PycharmProjects\ITC_hackathon\venv\lib\site-packages\mysql\connector\cursor_cext.py", line 258, in execute
    stmt = RE_PY_PARAM.sub(psub, stmt)
  File "C:\Users\Ari\PycharmProjects\ITC_hackathon\venv\lib\site-packages\mysql\connector\cursor_cext.py", line 68, in __call__
    "Not enough parameters for the SQL statement")
mysql.connector.errors.ProgrammingError: Not enough parameters for the SQL statement
2019-01-02 14:59:33,589 - root - ERROR - Not enough parameters for the SQL statement
Traceback (most recent call last):
  File "C:\Users\Ari\PycharmProjects\ITC_hackathon\venv\lib\site-packages\mysql\connector\cursor_cext.py", line 65, in __call__
    return self.params[index]
IndexError: tuple index out of range

During handling of the above exception, another exception occurred:

Traceback (most recent call last):
  File "C:\Users\Ari\PycharmProjects\ITC_hackathon\database_queries.py", line 132, in populate_skill_categories
    cur.execute(the_query, insert_string)
  File "C:\Users\Ari\PycharmProjects\ITC_hackathon\venv\lib\site-packages\mysql\connector\cursor_cext.py", line 258, in execute
    stmt = RE_PY_PARAM.sub(psub, stmt)
  File "C:\Users\Ari\PycharmProjects\ITC_hackathon\venv\lib\site-packages\mysql\connector\cursor_cext.py", line 68, in __call__
    "Not enough parameters for the SQL statement")
mysql.connector.errors.ProgrammingError: Not enough parameters for the SQL statement
2019-01-02 14:59:33,627 - root - ERROR - Not enough parameters for the SQL statement
Traceback (most recent call last):
  File "C:\Users\Ari\PycharmProjects\ITC_hackathon\venv\lib\site-packages\mysql\connector\cursor_cext.py", line 65, in __call__
    return self.params[index]
IndexError: tuple index out of range

During handling of the above exception, another exception occurred:

Traceback (most recent call last):
  File "C:\Users\Ari\PycharmProjects\ITC_hackathon\database_queries.py", line 132, in populate_skill_categories
    cur.execute(the_query, insert_string)
  File "C:\Users\Ari\PycharmProjects\ITC_hackathon\venv\lib\site-packages\mysql\connector\cursor_cext.py", line 258, in execute
    stmt = RE_PY_PARAM.sub(psub, stmt)
  File "C:\Users\Ari\PycharmProjects\ITC_hackathon\venv\lib\site-packages\mysql\connector\cursor_cext.py", line 68, in __call__
    "Not enough parameters for the SQL statement")
mysql.connector.errors.ProgrammingError: Not enough parameters for the SQL statement
2019-01-02 14:59:33,692 - root - ERROR - list index out of range
Traceback (most recent call last):
  File "C:\Users\Ari\PycharmProjects\ITC_hackathon\database_queries.py", line 152, in populate_skills
    insert_string = [result[0][0], details['skill']]
IndexError: list index out of range
2019-01-02 14:59:33,707 - root - ERROR - list index out of range
Traceback (most recent call last):
  File "C:\Users\Ari\PycharmProjects\ITC_hackathon\database_queries.py", line 152, in populate_skills
    insert_string = [result[0][0], details['skill']]
IndexError: list index out of range
2019-01-02 14:59:33,723 - root - ERROR - list index out of range
Traceback (most recent call last):
  File "C:\Users\Ari\PycharmProjects\ITC_hackathon\database_queries.py", line 152, in populate_skills
    insert_string = [result[0][0], details['skill']]
IndexError: list index out of range
2019-01-02 14:59:33,757 - root - ERROR - list index out of range
Traceback (most recent call last):
  File "C:\Users\Ari\PycharmProjects\ITC_hackathon\database_queries.py", line 152, in populate_skills
    insert_string = [result[0][0], details['skill']]
IndexError: list index out of range
2019-01-02 14:59:33,773 - root - ERROR - list index out of range
Traceback (most recent call last):
  File "C:\Users\Ari\PycharmProjects\ITC_hackathon\database_queries.py", line 152, in populate_skills
    insert_string = [result[0][0], details['skill']]
IndexError: list index out of range
2019-01-02 14:59:33,788 - root - ERROR - list index out of range
Traceback (most recent call last):
  File "C:\Users\Ari\PycharmProjects\ITC_hackathon\database_queries.py", line 152, in populate_skills
    insert_string = [result[0][0], details['skill']]
IndexError: list index out of range
2019-01-02 14:59:33,804 - root - ERROR - list index out of range
Traceback (most recent call last):
  File "C:\Users\Ari\PycharmProjects\ITC_hackathon\database_queries.py", line 152, in populate_skills
    insert_string = [result[0][0], details['skill']]
IndexError: list index out of range
2019-01-02 14:59:34,163 - root - ERROR - list index out of range
Traceback (most recent call last):
  File "C:\Users\Ari\PycharmProjects\ITC_hackathon\database_queries.py", line 228, in insert_person_skills
    insert_string = [the_username[0][0], the_skill[0][0]]
IndexError: list index out of range
2019-01-02 14:59:34,179 - root - ERROR - list index out of range
Traceback (most recent call last):
  File "C:\Users\Ari\PycharmProjects\ITC_hackathon\database_queries.py", line 228, in insert_person_skills
    insert_string = [the_username[0][0], the_skill[0][0]]
IndexError: list index out of range
2019-01-02 14:59:34,210 - root - ERROR - list index out of range
Traceback (most recent call last):
  File "C:\Users\Ari\PycharmProjects\ITC_hackathon\database_queries.py", line 228, in insert_person_skills
    insert_string = [the_username[0][0], the_skill[0][0]]
IndexError: list index out of range
2019-01-02 14:59:34,226 - root - ERROR - list index out of range
Traceback (most recent call last):
  File "C:\Users\Ari\PycharmProjects\ITC_hackathon\database_queries.py", line 228, in insert_person_skills
    insert_string = [the_username[0][0], the_skill[0][0]]
IndexError: list index out of range
2019-01-02 14:59:34,241 - root - ERROR - list index out of range
Traceback (most recent call last):
  File "C:\Users\Ari\PycharmProjects\ITC_hackathon\database_queries.py", line 228, in insert_person_skills
    insert_string = [the_username[0][0], the_skill[0][0]]
IndexError: list index out of range
2019-01-02 14:59:34,257 - root - ERROR - list index out of range
Traceback (most recent call last):
  File "C:\Users\Ari\PycharmProjects\ITC_hackathon\database_queries.py", line 228, in insert_person_skills
    insert_string = [the_username[0][0], the_skill[0][0]]
IndexError: list index out of range
2019-01-02 14:59:34,288 - root - ERROR - list index out of range
Traceback (most recent call last):
  File "C:\Users\Ari\PycharmProjects\ITC_hackathon\database_queries.py", line 228, in insert_person_skills
    insert_string = [the_username[0][0], the_skill[0][0]]
IndexError: list index out of range
2019-01-02 14:59:34,309 - root - ERROR - list index out of range
Traceback (most recent call last):
  File "C:\Users\Ari\PycharmProjects\ITC_hackathon\database_queries.py", line 228, in insert_person_skills
    insert_string = [the_username[0][0], the_skill[0][0]]
IndexError: list index out of range
2019-01-02 14:59:34,322 - root - ERROR - list index out of range
Traceback (most recent call last):
  File "C:\Users\Ari\PycharmProjects\ITC_hackathon\database_queries.py", line 228, in insert_person_skills
    insert_string = [the_username[0][0], the_skill[0][0]]
IndexError: list index out of range
2019-01-02 14:59:34,337 - root - ERROR - list index out of range
Traceback (most recent call last):
  File "C:\Users\Ari\PycharmProjects\ITC_hackathon\database_queries.py", line 228, in insert_person_skills
    insert_string = [the_username[0][0], the_skill[0][0]]
IndexError: list index out of range
2019-01-02 14:59:34,353 - root - ERROR - list index out of range
Traceback (most recent call last):
  File "C:\Users\Ari\PycharmProjects\ITC_hackathon\database_queries.py", line 228, in insert_person_skills
    insert_string = [the_username[0][0], the_skill[0][0]]
IndexError: list index out of range
2019-01-02 14:59:34,384 - root - ERROR - list index out of range
Traceback (most recent call last):
  File "C:\Users\Ari\PycharmProjects\ITC_hackathon\database_queries.py", line 276, in create_job
    insert_string = [the_username[0][0], the_skill[0][0], the_status[0][0]]
IndexError: list index out of range
2019-01-02 14:59:34,400 - root - ERROR - list index out of range
Traceback (most recent call last):
  File "C:\Users\Ari\PycharmProjects\ITC_hackathon\database_queries.py", line 276, in create_job
    insert_string = [the_username[0][0], the_skill[0][0], the_status[0][0]]
IndexError: list index out of range
2019-01-02 14:59:34,416 - root - ERROR - list index out of range
Traceback (most recent call last):
  File "C:\Users\Ari\PycharmProjects\ITC_hackathon\database_queries.py", line 276, in create_job
    insert_string = [the_username[0][0], the_skill[0][0], the_status[0][0]]
IndexError: list index out of range
2019-01-02 14:59:34,431 - root - ERROR - list index out of range
Traceback (most recent call last):
  File "C:\Users\Ari\PycharmProjects\ITC_hackathon\database_queries.py", line 276, in create_job
    insert_string = [the_username[0][0], the_skill[0][0], the_status[0][0]]
IndexError: list index out of range
2019-01-02 14:59:34,462 - root - ERROR - list index out of range
Traceback (most recent call last):
  File "C:\Users\Ari\PycharmProjects\ITC_hackathon\database_queries.py", line 276, in create_job
    insert_string = [the_username[0][0], the_skill[0][0], the_status[0][0]]
IndexError: list index out of range
2019-01-02 14:59:34,478 - root - ERROR - list index out of range
Traceback (most recent call last):
  File "C:\Users\Ari\PycharmProjects\ITC_hackathon\database_queries.py", line 276, in create_job
    insert_string = [the_username[0][0], the_skill[0][0], the_status[0][0]]
IndexError: list index out of range
2019-01-02 14:59:34,494 - root - ERROR - list index out of range
Traceback (most recent call last):
  File "C:\Users\Ari\PycharmProjects\ITC_hackathon\database_queries.py", line 276, in create_job
    insert_string = [the_username[0][0], the_skill[0][0], the_status[0][0]]
IndexError: list index out of range
2019-01-02 14:59:34,509 - root - ERROR - list index out of range
Traceback (most recent call last):
  File "C:\Users\Ari\PycharmProjects\ITC_hackathon\database_queries.py", line 276, in create_job
    insert_string = [the_username[0][0], the_skill[0][0], the_status[0][0]]
IndexError: list index out of range
2019-01-02 14:59:34,541 - root - ERROR - list index out of range
Traceback (most recent call last):
  File "C:\Users\Ari\PycharmProjects\ITC_hackathon\database_queries.py", line 276, in create_job
    insert_string = [the_username[0][0], the_skill[0][0], the_status[0][0]]
IndexError: list index out of range
2019-01-02 14:59:34,565 - root - ERROR - list index out of range
Traceback (most recent call last):
  File "C:\Users\Ari\PycharmProjects\ITC_hackathon\database_queries.py", line 276, in create_job
    insert_string = [the_username[0][0], the_skill[0][0], the_status[0][0]]
IndexError: list index out of range
2019-01-02 14:59:34,584 - root - ERROR - list index out of range
Traceback (most recent call last):
  File "C:\Users\Ari\PycharmProjects\ITC_hackathon\database_queries.py", line 276, in create_job
    insert_string = [the_username[0][0], the_skill[0][0], the_status[0][0]]
IndexError: list index out of range
2019-01-02 14:59:34,602 - root - ERROR - list index out of range
Traceback (most recent call last):
  File "C:\Users\Ari\PycharmProjects\ITC_hackathon\database_queries.py", line 276, in create_job
    insert_string = [the_username[0][0], the_skill[0][0], the_status[0][0]]
IndexError: list index out of range
2019-01-02 15:01:24,205 - root - INFO - Database initialized.
2019-01-02 15:01:24,298 - root - INFO - "users" table initialized.
2019-01-02 15:01:24,330 - root - INFO - "skill_categories" table initialized.
2019-01-02 15:01:24,361 - root - INFO - "skills" table initialized.
2019-01-02 15:01:24,423 - root - INFO - "person_skills" table initialized.
2019-01-02 15:01:24,455 - root - INFO - "statuses" table initialized.
2019-01-02 15:01:24,486 - root - INFO - "jobs" table initialized.
2019-01-02 15:01:24,486 - root - INFO - Complete database initialized.
2019-01-02 15:01:24,539 - root - ERROR - 1062 (23000): Duplicate entry 'Ari' for key 'username'
Traceback (most recent call last):
  File "C:\Users\Ari\PycharmProjects\ITC_hackathon\venv\lib\site-packages\mysql\connector\connection_cext.py", line 392, in cmd_query
    raw_as_string=raw_as_string)
_mysql_connector.MySQLInterfaceError: Duplicate entry 'Ari' for key 'username'

During handling of the above exception, another exception occurred:

Traceback (most recent call last):
  File "C:\Users\Ari\PycharmProjects\ITC_hackathon\database_queries.py", line 200, in insert_user_details
    cur.execute(the_query, insert_string)
  File "C:\Users\Ari\PycharmProjects\ITC_hackathon\venv\lib\site-packages\mysql\connector\cursor_cext.py", line 266, in execute
    raw_as_string=self._raw_as_string)
  File "C:\Users\Ari\PycharmProjects\ITC_hackathon\venv\lib\site-packages\mysql\connector\connection_cext.py", line 395, in cmd_query
    sqlstate=exc.sqlstate)
mysql.connector.errors.IntegrityError: 1062 (23000): Duplicate entry 'Ari' for key 'username'
2019-01-02 15:01:24,587 - root - ERROR - 1062 (23000): Duplicate entry 'Ilona' for key 'username'
Traceback (most recent call last):
  File "C:\Users\Ari\PycharmProjects\ITC_hackathon\venv\lib\site-packages\mysql\connector\connection_cext.py", line 392, in cmd_query
    raw_as_string=raw_as_string)
_mysql_connector.MySQLInterfaceError: Duplicate entry 'Ilona' for key 'username'

During handling of the above exception, another exception occurred:

Traceback (most recent call last):
  File "C:\Users\Ari\PycharmProjects\ITC_hackathon\database_queries.py", line 200, in insert_user_details
    cur.execute(the_query, insert_string)
  File "C:\Users\Ari\PycharmProjects\ITC_hackathon\venv\lib\site-packages\mysql\connector\cursor_cext.py", line 266, in execute
    raw_as_string=self._raw_as_string)
  File "C:\Users\Ari\PycharmProjects\ITC_hackathon\venv\lib\site-packages\mysql\connector\connection_cext.py", line 395, in cmd_query
    sqlstate=exc.sqlstate)
mysql.connector.errors.IntegrityError: 1062 (23000): Duplicate entry 'Ilona' for key 'username'
2019-01-02 15:01:24,633 - root - ERROR - 1062 (23000): Duplicate entry 'Jeremy' for key 'username'
Traceback (most recent call last):
  File "C:\Users\Ari\PycharmProjects\ITC_hackathon\venv\lib\site-packages\mysql\connector\connection_cext.py", line 392, in cmd_query
    raw_as_string=raw_as_string)
_mysql_connector.MySQLInterfaceError: Duplicate entry 'Jeremy' for key 'username'

During handling of the above exception, another exception occurred:

Traceback (most recent call last):
  File "C:\Users\Ari\PycharmProjects\ITC_hackathon\database_queries.py", line 200, in insert_user_details
    cur.execute(the_query, insert_string)
  File "C:\Users\Ari\PycharmProjects\ITC_hackathon\venv\lib\site-packages\mysql\connector\cursor_cext.py", line 266, in execute
    raw_as_string=self._raw_as_string)
  File "C:\Users\Ari\PycharmProjects\ITC_hackathon\venv\lib\site-packages\mysql\connector\connection_cext.py", line 395, in cmd_query
    sqlstate=exc.sqlstate)
mysql.connector.errors.IntegrityError: 1062 (23000): Duplicate entry 'Jeremy' for key 'username'
2019-01-02 15:01:24,680 - root - ERROR - 1062 (23000): Duplicate entry 'Remy' for key 'username'
Traceback (most recent call last):
  File "C:\Users\Ari\PycharmProjects\ITC_hackathon\venv\lib\site-packages\mysql\connector\connection_cext.py", line 392, in cmd_query
    raw_as_string=raw_as_string)
_mysql_connector.MySQLInterfaceError: Duplicate entry 'Remy' for key 'username'

During handling of the above exception, another exception occurred:

Traceback (most recent call last):
  File "C:\Users\Ari\PycharmProjects\ITC_hackathon\database_queries.py", line 200, in insert_user_details
    cur.execute(the_query, insert_string)
  File "C:\Users\Ari\PycharmProjects\ITC_hackathon\venv\lib\site-packages\mysql\connector\cursor_cext.py", line 266, in execute
    raw_as_string=self._raw_as_string)
  File "C:\Users\Ari\PycharmProjects\ITC_hackathon\venv\lib\site-packages\mysql\connector\connection_cext.py", line 395, in cmd_query
    sqlstate=exc.sqlstate)
mysql.connector.errors.IntegrityError: 1062 (23000): Duplicate entry 'Remy' for key 'username'
2019-01-02 15:01:24,712 - root - ERROR - 1062 (23000): Duplicate entry 'Yair' for key 'username'
Traceback (most recent call last):
  File "C:\Users\Ari\PycharmProjects\ITC_hackathon\venv\lib\site-packages\mysql\connector\connection_cext.py", line 392, in cmd_query
    raw_as_string=raw_as_string)
_mysql_connector.MySQLInterfaceError: Duplicate entry 'Yair' for key 'username'

During handling of the above exception, another exception occurred:

Traceback (most recent call last):
  File "C:\Users\Ari\PycharmProjects\ITC_hackathon\database_queries.py", line 200, in insert_user_details
    cur.execute(the_query, insert_string)
  File "C:\Users\Ari\PycharmProjects\ITC_hackathon\venv\lib\site-packages\mysql\connector\cursor_cext.py", line 266, in execute
    raw_as_string=self._raw_as_string)
  File "C:\Users\Ari\PycharmProjects\ITC_hackathon\venv\lib\site-packages\mysql\connector\connection_cext.py", line 395, in cmd_query
    sqlstate=exc.sqlstate)
mysql.connector.errors.IntegrityError: 1062 (23000): Duplicate entry 'Yair' for key 'username'
2019-01-02 15:01:24,727 - root - ERROR - Not enough parameters for the SQL statement
Traceback (most recent call last):
  File "C:\Users\Ari\PycharmProjects\ITC_hackathon\venv\lib\site-packages\mysql\connector\cursor_cext.py", line 65, in __call__
    return self.params[index]
IndexError: tuple index out of range

During handling of the above exception, another exception occurred:

Traceback (most recent call last):
  File "C:\Users\Ari\PycharmProjects\ITC_hackathon\database_queries.py", line 133, in populate_skill_categories
    cur.execute(the_query, insert_string)
  File "C:\Users\Ari\PycharmProjects\ITC_hackathon\venv\lib\site-packages\mysql\connector\cursor_cext.py", line 258, in execute
    stmt = RE_PY_PARAM.sub(psub, stmt)
  File "C:\Users\Ari\PycharmProjects\ITC_hackathon\venv\lib\site-packages\mysql\connector\cursor_cext.py", line 68, in __call__
    "Not enough parameters for the SQL statement")
mysql.connector.errors.ProgrammingError: Not enough parameters for the SQL statement
2019-01-02 15:01:24,743 - root - ERROR - Not enough parameters for the SQL statement
Traceback (most recent call last):
  File "C:\Users\Ari\PycharmProjects\ITC_hackathon\venv\lib\site-packages\mysql\connector\cursor_cext.py", line 65, in __call__
    return self.params[index]
IndexError: tuple index out of range

During handling of the above exception, another exception occurred:

Traceback (most recent call last):
  File "C:\Users\Ari\PycharmProjects\ITC_hackathon\database_queries.py", line 133, in populate_skill_categories
    cur.execute(the_query, insert_string)
  File "C:\Users\Ari\PycharmProjects\ITC_hackathon\venv\lib\site-packages\mysql\connector\cursor_cext.py", line 258, in execute
    stmt = RE_PY_PARAM.sub(psub, stmt)
  File "C:\Users\Ari\PycharmProjects\ITC_hackathon\venv\lib\site-packages\mysql\connector\cursor_cext.py", line 68, in __call__
    "Not enough parameters for the SQL statement")
mysql.connector.errors.ProgrammingError: Not enough parameters for the SQL statement
2019-01-02 15:01:24,758 - root - ERROR - Not enough parameters for the SQL statement
Traceback (most recent call last):
  File "C:\Users\Ari\PycharmProjects\ITC_hackathon\venv\lib\site-packages\mysql\connector\cursor_cext.py", line 65, in __call__
    return self.params[index]
IndexError: tuple index out of range

During handling of the above exception, another exception occurred:

Traceback (most recent call last):
  File "C:\Users\Ari\PycharmProjects\ITC_hackathon\database_queries.py", line 133, in populate_skill_categories
    cur.execute(the_query, insert_string)
  File "C:\Users\Ari\PycharmProjects\ITC_hackathon\venv\lib\site-packages\mysql\connector\cursor_cext.py", line 258, in execute
    stmt = RE_PY_PARAM.sub(psub, stmt)
  File "C:\Users\Ari\PycharmProjects\ITC_hackathon\venv\lib\site-packages\mysql\connector\cursor_cext.py", line 68, in __call__
    "Not enough parameters for the SQL statement")
mysql.connector.errors.ProgrammingError: Not enough parameters for the SQL statement
2019-01-02 15:01:24,790 - root - ERROR - Not enough parameters for the SQL statement
Traceback (most recent call last):
  File "C:\Users\Ari\PycharmProjects\ITC_hackathon\venv\lib\site-packages\mysql\connector\cursor_cext.py", line 65, in __call__
    return self.params[index]
IndexError: tuple index out of range

During handling of the above exception, another exception occurred:

Traceback (most recent call last):
  File "C:\Users\Ari\PycharmProjects\ITC_hackathon\database_queries.py", line 133, in populate_skill_categories
    cur.execute(the_query, insert_string)
  File "C:\Users\Ari\PycharmProjects\ITC_hackathon\venv\lib\site-packages\mysql\connector\cursor_cext.py", line 258, in execute
    stmt = RE_PY_PARAM.sub(psub, stmt)
  File "C:\Users\Ari\PycharmProjects\ITC_hackathon\venv\lib\site-packages\mysql\connector\cursor_cext.py", line 68, in __call__
    "Not enough parameters for the SQL statement")
mysql.connector.errors.ProgrammingError: Not enough parameters for the SQL statement
2019-01-02 15:01:24,805 - root - ERROR - list index out of range
Traceback (most recent call last):
  File "C:\Users\Ari\PycharmProjects\ITC_hackathon\database_queries.py", line 153, in populate_skills
    insert_string = [result[0][0], details['skill']]
IndexError: list index out of range
2019-01-02 15:01:24,821 - root - ERROR - list index out of range
Traceback (most recent call last):
  File "C:\Users\Ari\PycharmProjects\ITC_hackathon\database_queries.py", line 153, in populate_skills
    insert_string = [result[0][0], details['skill']]
IndexError: list index out of range
2019-01-02 15:01:24,837 - root - ERROR - list index out of range
Traceback (most recent call last):
  File "C:\Users\Ari\PycharmProjects\ITC_hackathon\database_queries.py", line 153, in populate_skills
    insert_string = [result[0][0], details['skill']]
IndexError: list index out of range
2019-01-02 15:01:24,852 - root - ERROR - list index out of range
Traceback (most recent call last):
  File "C:\Users\Ari\PycharmProjects\ITC_hackathon\database_queries.py", line 153, in populate_skills
    insert_string = [result[0][0], details['skill']]
IndexError: list index out of range
2019-01-02 15:01:24,883 - root - ERROR - list index out of range
Traceback (most recent call last):
  File "C:\Users\Ari\PycharmProjects\ITC_hackathon\database_queries.py", line 153, in populate_skills
    insert_string = [result[0][0], details['skill']]
IndexError: list index out of range
2019-01-02 15:01:24,899 - root - ERROR - list index out of range
Traceback (most recent call last):
  File "C:\Users\Ari\PycharmProjects\ITC_hackathon\database_queries.py", line 153, in populate_skills
    insert_string = [result[0][0], details['skill']]
IndexError: list index out of range
2019-01-02 15:01:24,915 - root - ERROR - list index out of range
Traceback (most recent call last):
  File "C:\Users\Ari\PycharmProjects\ITC_hackathon\database_queries.py", line 153, in populate_skills
    insert_string = [result[0][0], details['skill']]
IndexError: list index out of range
2019-01-02 15:01:24,977 - root - ERROR - 1062 (23000): Duplicate entry 'Available' for key 'status'
Traceback (most recent call last):
  File "C:\Users\Ari\PycharmProjects\ITC_hackathon\venv\lib\site-packages\mysql\connector\connection_cext.py", line 392, in cmd_query
    raw_as_string=raw_as_string)
_mysql_connector.MySQLInterfaceError: Duplicate entry 'Available' for key 'status'

During handling of the above exception, another exception occurred:

Traceback (most recent call last):
  File "C:\Users\Ari\PycharmProjects\ITC_hackathon\database_queries.py", line 180, in populate_statuses
    cur.execute(the_query, insert_string)
  File "C:\Users\Ari\PycharmProjects\ITC_hackathon\venv\lib\site-packages\mysql\connector\cursor_cext.py", line 266, in execute
    raw_as_string=self._raw_as_string)
  File "C:\Users\Ari\PycharmProjects\ITC_hackathon\venv\lib\site-packages\mysql\connector\connection_cext.py", line 395, in cmd_query
    sqlstate=exc.sqlstate)
mysql.connector.errors.IntegrityError: 1062 (23000): Duplicate entry 'Available' for key 'status'
2019-01-02 15:01:25,008 - root - ERROR - 1062 (23000): Duplicate entry 'Pending' for key 'status'
Traceback (most recent call last):
  File "C:\Users\Ari\PycharmProjects\ITC_hackathon\venv\lib\site-packages\mysql\connector\connection_cext.py", line 392, in cmd_query
    raw_as_string=raw_as_string)
_mysql_connector.MySQLInterfaceError: Duplicate entry 'Pending' for key 'status'

During handling of the above exception, another exception occurred:

Traceback (most recent call last):
  File "C:\Users\Ari\PycharmProjects\ITC_hackathon\database_queries.py", line 180, in populate_statuses
    cur.execute(the_query, insert_string)
  File "C:\Users\Ari\PycharmProjects\ITC_hackathon\venv\lib\site-packages\mysql\connector\cursor_cext.py", line 266, in execute
    raw_as_string=self._raw_as_string)
  File "C:\Users\Ari\PycharmProjects\ITC_hackathon\venv\lib\site-packages\mysql\connector\connection_cext.py", line 395, in cmd_query
    sqlstate=exc.sqlstate)
mysql.connector.errors.IntegrityError: 1062 (23000): Duplicate entry 'Pending' for key 'status'
2019-01-02 15:01:25,040 - root - ERROR - 1062 (23000): Duplicate entry 'Complete' for key 'status'
Traceback (most recent call last):
  File "C:\Users\Ari\PycharmProjects\ITC_hackathon\venv\lib\site-packages\mysql\connector\connection_cext.py", line 392, in cmd_query
    raw_as_string=raw_as_string)
_mysql_connector.MySQLInterfaceError: Duplicate entry 'Complete' for key 'status'

During handling of the above exception, another exception occurred:

Traceback (most recent call last):
  File "C:\Users\Ari\PycharmProjects\ITC_hackathon\database_queries.py", line 180, in populate_statuses
    cur.execute(the_query, insert_string)
  File "C:\Users\Ari\PycharmProjects\ITC_hackathon\venv\lib\site-packages\mysql\connector\cursor_cext.py", line 266, in execute
    raw_as_string=self._raw_as_string)
  File "C:\Users\Ari\PycharmProjects\ITC_hackathon\venv\lib\site-packages\mysql\connector\connection_cext.py", line 395, in cmd_query
    sqlstate=exc.sqlstate)
mysql.connector.errors.IntegrityError: 1062 (23000): Duplicate entry 'Complete' for key 'status'
2019-01-02 15:01:25,069 - root - ERROR - list index out of range
Traceback (most recent call last):
  File "C:\Users\Ari\PycharmProjects\ITC_hackathon\database_queries.py", line 229, in insert_person_skills
    insert_string = [the_username[0][0], the_skill[0][0]]
IndexError: list index out of range
2019-01-02 15:01:25,088 - root - ERROR - list index out of range
Traceback (most recent call last):
  File "C:\Users\Ari\PycharmProjects\ITC_hackathon\database_queries.py", line 229, in insert_person_skills
    insert_string = [the_username[0][0], the_skill[0][0]]
IndexError: list index out of range
2019-01-02 15:01:25,104 - root - ERROR - list index out of range
Traceback (most recent call last):
  File "C:\Users\Ari\PycharmProjects\ITC_hackathon\database_queries.py", line 229, in insert_person_skills
    insert_string = [the_username[0][0], the_skill[0][0]]
IndexError: list index out of range
2019-01-02 15:01:25,119 - root - ERROR - list index out of range
Traceback (most recent call last):
  File "C:\Users\Ari\PycharmProjects\ITC_hackathon\database_queries.py", line 229, in insert_person_skills
    insert_string = [the_username[0][0], the_skill[0][0]]
IndexError: list index out of range
2019-01-02 15:01:25,135 - root - ERROR - list index out of range
Traceback (most recent call last):
  File "C:\Users\Ari\PycharmProjects\ITC_hackathon\database_queries.py", line 229, in insert_person_skills
    insert_string = [the_username[0][0], the_skill[0][0]]
IndexError: list index out of range
2019-01-02 15:01:25,166 - root - ERROR - list index out of range
Traceback (most recent call last):
  File "C:\Users\Ari\PycharmProjects\ITC_hackathon\database_queries.py", line 229, in insert_person_skills
    insert_string = [the_username[0][0], the_skill[0][0]]
IndexError: list index out of range
2019-01-02 15:01:25,182 - root - ERROR - list index out of range
Traceback (most recent call last):
  File "C:\Users\Ari\PycharmProjects\ITC_hackathon\database_queries.py", line 229, in insert_person_skills
    insert_string = [the_username[0][0], the_skill[0][0]]
IndexError: list index out of range
2019-01-02 15:01:25,197 - root - ERROR - list index out of range
Traceback (most recent call last):
  File "C:\Users\Ari\PycharmProjects\ITC_hackathon\database_queries.py", line 229, in insert_person_skills
    insert_string = [the_username[0][0], the_skill[0][0]]
IndexError: list index out of range
2019-01-02 15:01:25,213 - root - ERROR - list index out of range
Traceback (most recent call last):
  File "C:\Users\Ari\PycharmProjects\ITC_hackathon\database_queries.py", line 229, in insert_person_skills
    insert_string = [the_username[0][0], the_skill[0][0]]
IndexError: list index out of range
2019-01-02 15:01:25,229 - root - ERROR - list index out of range
Traceback (most recent call last):
  File "C:\Users\Ari\PycharmProjects\ITC_hackathon\database_queries.py", line 229, in insert_person_skills
    insert_string = [the_username[0][0], the_skill[0][0]]
IndexError: list index out of range
2019-01-02 15:01:25,260 - root - ERROR - list index out of range
Traceback (most recent call last):
  File "C:\Users\Ari\PycharmProjects\ITC_hackathon\database_queries.py", line 229, in insert_person_skills
    insert_string = [the_username[0][0], the_skill[0][0]]
IndexError: list index out of range
2019-01-02 15:01:25,275 - root - ERROR - list index out of range
Traceback (most recent call last):
  File "C:\Users\Ari\PycharmProjects\ITC_hackathon\database_queries.py", line 277, in create_job
    insert_string = [the_username[0][0], the_skill[0][0], the_status[0][0]]
IndexError: list index out of range
2019-01-02 15:01:25,291 - root - ERROR - list index out of range
Traceback (most recent call last):
  File "C:\Users\Ari\PycharmProjects\ITC_hackathon\database_queries.py", line 277, in create_job
    insert_string = [the_username[0][0], the_skill[0][0], the_status[0][0]]
IndexError: list index out of range
2019-01-02 15:01:25,322 - root - ERROR - list index out of range
Traceback (most recent call last):
  File "C:\Users\Ari\PycharmProjects\ITC_hackathon\database_queries.py", line 277, in create_job
    insert_string = [the_username[0][0], the_skill[0][0], the_status[0][0]]
IndexError: list index out of range
2019-01-02 15:01:25,338 - root - ERROR - list index out of range
Traceback (most recent call last):
  File "C:\Users\Ari\PycharmProjects\ITC_hackathon\database_queries.py", line 277, in create_job
    insert_string = [the_username[0][0], the_skill[0][0], the_status[0][0]]
IndexError: list index out of range
2019-01-02 15:01:25,354 - root - ERROR - list index out of range
Traceback (most recent call last):
  File "C:\Users\Ari\PycharmProjects\ITC_hackathon\database_queries.py", line 277, in create_job
    insert_string = [the_username[0][0], the_skill[0][0], the_status[0][0]]
IndexError: list index out of range
2019-01-02 15:01:25,385 - root - ERROR - list index out of range
Traceback (most recent call last):
  File "C:\Users\Ari\PycharmProjects\ITC_hackathon\database_queries.py", line 277, in create_job
    insert_string = [the_username[0][0], the_skill[0][0], the_status[0][0]]
IndexError: list index out of range
2019-01-02 15:01:25,400 - root - ERROR - list index out of range
Traceback (most recent call last):
  File "C:\Users\Ari\PycharmProjects\ITC_hackathon\database_queries.py", line 277, in create_job
    insert_string = [the_username[0][0], the_skill[0][0], the_status[0][0]]
IndexError: list index out of range
2019-01-02 15:01:25,416 - root - ERROR - list index out of range
Traceback (most recent call last):
  File "C:\Users\Ari\PycharmProjects\ITC_hackathon\database_queries.py", line 277, in create_job
    insert_string = [the_username[0][0], the_skill[0][0], the_status[0][0]]
IndexError: list index out of range
2019-01-02 15:01:25,432 - root - ERROR - list index out of range
Traceback (most recent call last):
  File "C:\Users\Ari\PycharmProjects\ITC_hackathon\database_queries.py", line 277, in create_job
    insert_string = [the_username[0][0], the_skill[0][0], the_status[0][0]]
IndexError: list index out of range
2019-01-02 15:01:25,463 - root - ERROR - list index out of range
Traceback (most recent call last):
  File "C:\Users\Ari\PycharmProjects\ITC_hackathon\database_queries.py", line 277, in create_job
    insert_string = [the_username[0][0], the_skill[0][0], the_status[0][0]]
IndexError: list index out of range
2019-01-02 15:01:25,479 - root - ERROR - list index out of range
Traceback (most recent call last):
  File "C:\Users\Ari\PycharmProjects\ITC_hackathon\database_queries.py", line 277, in create_job
    insert_string = [the_username[0][0], the_skill[0][0], the_status[0][0]]
IndexError: list index out of range
2019-01-02 15:01:25,494 - root - ERROR - list index out of range
Traceback (most recent call last):
  File "C:\Users\Ari\PycharmProjects\ITC_hackathon\database_queries.py", line 277, in create_job
    insert_string = [the_username[0][0], the_skill[0][0], the_status[0][0]]
IndexError: list index out of range
2019-01-02 15:05:19,665 - root - INFO - Database initialized.
2019-01-02 15:05:20,136 - root - INFO - "users" table initialized.
2019-01-02 15:05:20,743 - root - INFO - "skill_categories" table initialized.
2019-01-02 15:05:21,171 - root - INFO - "skills" table initialized.
2019-01-02 15:05:21,780 - root - INFO - "person_skills" table initialized.
2019-01-02 15:05:22,191 - root - INFO - "statuses" table initialized.
2019-01-02 15:05:22,923 - root - INFO - "jobs" table initialized.
2019-01-02 15:05:22,923 - root - INFO - Complete database initialized.
2019-01-02 15:08:50,844 - root - INFO - Database initialized.
2019-01-02 15:08:52,197 - root - INFO - "users" table initialized.
2019-01-02 15:08:52,666 - root - INFO - "skill_categories" table initialized.
2019-01-02 15:08:53,122 - root - INFO - "skills" table initialized.
2019-01-02 15:08:53,759 - root - INFO - "person_skills" table initialized.
2019-01-02 15:08:54,286 - root - INFO - "statuses" table initialized.
2019-01-02 15:08:55,160 - root - INFO - "jobs" table initialized.
2019-01-02 15:08:55,160 - root - INFO - Complete database initialized.
